Workbook

Sheet Sheet1
A1: Tenant Directory
A2: Exported On: 05/13/2025 04:01 PM
A4: Tenants: Active
A5: Tenant Status: Current
A6: Tenant Type: Financially Responsible
A7: Entities: Active Properties
A9: Property Name | B9: Unit | C9: Tenant | D9: Tenant Street Address 1 | E9: Tenant City | F9: Tenant State | G9: Tenant Zip | H9: First Name | I9: Last Name
A10: S0001 - 90 Park St | B10: Retail 1 | C10: Bueno Grocery LLC | D10: 98-100 Park Street | E10: Hartford | F10: CT | G10: 06106 | H10: Jose | I10: Bueno
A11: S0001 - 90 Park St | B11: Retail 2 | C11: El Bohio Cafe 2 LLC | D11: 90-92 Park Street | E11: Hartford | F11: CT | G11: 06106 | H11: Maritza | I11: Estrada
A12: S0001 - 90 Park St | B12: 6 | C12: Colon, Joanna | D12: 96 Park Street | E12: Hartford | F12: CT | G12: 06106 | H12: Joanna | I12: Colon
A13: S0001 - 90 Park St | B13: 7 - old | C13: Santiago, German | D13: 94 Park Street | E13: Hartford | F13: CT | G13: 06106 | H13: German | I13: Santiago
A14: S0001 - 90 Park St | B14: 10 | C14: Estrada, Maritza | D14: 96 Park Street | E14: Hartford | F14: CT | G14: 06106 | H14: Maritza | I14: Estrada
A15: S0001 - 90 Park St | B15: 5 - B | C15: Valdez, Rosa M. | D15: 94 Park Street | E15: Hartford | F15: CT | G15: 06106 | H15: Rosa | I15: Valdez
A16: S0001 - 90 Park St | B16: 5 - B | C16: Santiago , Jose A. | D16: 94 Park Street | E16: Hartford | F16: CT | G16: 06106 | H16: Jose | I16: Santiago
A17: S0001 - 90 Park St | B17: 5 - C | C17: Lorenzo , Wilbert | D17: 94 Park Street | E17: Hartford | F17: CT | G17: 06106 | H17: Wilbert | I17: Lorenzo
A18: S0001 - 90 Park St | B18: 9 | C18: Rodriguez , Jessica | D18: 94 Park Street | E18: Hartford | F18: CT | G18: 06106 | H18: Jessica | I18: Rodriguez
A19: S0001 - 90 Park St | B19: 5 - D | C19: Cintron, Steve | D19: 94 Park Street | E19: Hartford | F19: CT | G19: 06106 | H19: Steve | I19: Cintron
A20: S0001 - 90 Park St | B20: 4 | C20: Trevino, Amanda P. | D20: 96 Park Street | E20: Hartford | F20: CT | G20: 06106 | H20: Amanda | I20: Trevino
... A50: S0007 - 36 Whit | B50: 1W | C50: Wallace, Taurie M. | D50: 36 Whitmore Street | E50: Hartford | F50: CT | G50: 06114 | H50: Taurie | I50: Wallace
A51: S0007 - 36 Whit | B51: 3W | C51: Gonzalez, Jeanete Mercedez | H51: Jeanete Mercedez | I51: Gonzalez
A52: S0007 - 36 Whit | B52: 1E | C52: Vargas-Espinosa, Carmen R. | D52: 36 Whitmore Street | E52: Hartford | F52: CT | G52: 06114 | H52: Carmen | I52: Vargas-Espinosa
A53: S0008 - 38 Whit | B53: 2W | C53: Jordan , Samantha L. | D53: 38 Whitmore Street | E53: Hartford | F53: CT | G53: 06114 | H53: Samantha | I53: Jordan
A54: S0008 - 38 Whit | B54: 2E | C54: Thomas , Tiffani | D54: 38 Whitmore Street | E54: Hartford | F54: CT | G54: 06114 | H54: Tiffani | I54: Thomas
A55: S0008 - 38 Whit | B55: 1W | C55: Torres, Sylvanna | D55: 38 Whitmore Street | E55: Hartford | F55: CT | G55: 06114 | H55: Sylvanna | I55: Torres
A56: S0008 - 38 Whit | B56: 3E | C56: Negron-Soto, Migdalia | D56: 38 Whitmore Street | E56: Hartford | F56: CT | G56: 06114 | H56: Migdalia | I56: Negron-Soto
A57: S0008 - 38 Whit | B57: 1E | C57: Smith, Toccara D. | D57: 38 Whitmore Street | E57: Hartford | F57: CT | G57: 06114 | H57: Toccara | I57: Smith
A58: S0008 - 38 Whit | B58: 3W | C58: Arroyo-Mendez, Sanya M. | D58: 38 Whitmore Street | E58: Hartford | F58: CT | G58: 06114 | H58: Sanya | I58: Arroyo-Mendez
A59: S0011 - 110 Martin | B59: 1 | C59: Smith, Roxanne | D59: 110 Martin St | E59: Hartford | F59: CT | G59: 06120 | H59: Roxanne | I59: Smith
A60: S0011 - 110 Martin | B60: 2 | C60: Leach, Tammy | D60: 110 Martin St | E60: Hartford | F60: CT | G60: 06120 | H60: Tammy | I60: Leach
A61: S0011 - 110 Martin | B61: 5 | C61: Barno Swain, Lerona | D61: 110 Martin St | E61: Hartford | F61: CT | G61: 06120 | H61: Lerona | I61: Barno Swain
A62: S0011 - 110 Martin | B62: 7 | C62: Coleman, Theresa | D62: 110 Martin St | E62: Hartford | F62: CT | G62: 06120 | H62: Theresa | I62: Coleman
A63: S0011 - 110 Martin | B63: 4 | C63: Rivera, Salena R. | D63: 110 Martin St | E63: Hartford | F63: CT | G63: 06120 | H63: Salena | I63: Rivera
... A96: S0018 - 90 Edwards | B96: 90C | C96: Mara Branch , Claryssa | D96: 90 Edwards St | E96: Hartford | F96: CT | G96: 06010 | H96: Claryssa | I96: Mara Branch
A97: S0020 - 31 Park | B97: Retail 1 | C97: Danny's Grocery | D97: 33 Park St | E97: Hartford | F97: CT | G97: 06106
A98: S0021 - 69 Park | B98: COM 67 Park | C98: Boostmobile | D98: 67 Park St | E98: Hartford | F98: CT | G98: 61606 | H98: BOOST | I98: Mobile
A99: S0021 - 69 Park | B99: 201 | C99: Corona, Domitila | D99: 67-69 Park St | E99: Hartford | F99: CT | G99: 61606 | H99: Domitila | I99: Corona
A100: S0021 - 69 Park | B100: 202 | C100: Nunez, Maria | D100: 67-69 Park St | E100: Hartford | F100: CT | G100: 61606 | H100: Maria | I100: Nunez
A101: S0021 - 69 Park | B101: 302 | C101: Lockhart, Omyra | D101: 67-69 Park St | E101: Hartford | F101: CT | G101: 61606 | H101: Omyra | I101: Lockhart
A102: S0021 - 69 Park | B102: COM 75 Park | C102: Mi Sabor Restaurant | D102: 75 Park St | E102: Hartford | F102: CT | G102: 61606 | H102: VICTORINO | I102: RODRIGUEZ
A103: S0021 - 69 Park | B103: 301 | C103: Garcia, Nelida | D103: 67-69 Park St | E103: Hartford | F103: CT | G103: 61606 | H103: Nelida | I103: Garcia
...

Sheet Sheet2
A1: First_name | B1: Last_name | C1: Organization | D1: Address1 | E1: Address2 | F1: City | G1: State | H1: Zip | I1: Country_non-US | J1: Tenants phone # | K1: Make & model (Car1) | L1: Color | M1: License plate number | N1: Make & model (Car2) | O1: Color | P1: License plate number | Q1: Make & model (Car3) | R1: Color | S1: License plate number
A2: =Sheet1!H10 -> Jose | B2: =Sheet1!I10 -> Bueno | C2: =Sheet1!A10 -> S0001 - 90 Park St | D2: =Sheet1!D10 -> 98-100 Park Street | E2: =Sheet1!B10 -> Retail 1 | F2: =Sheet1!E10 -> Hartford | G2: =Sheet1!F10 -> CT | H2: =Sheet1!G10 -> 06106 | J2: (860) 951-1559
A3: =Sheet1!H11 -> Maritza | B3: =Sheet1!I11 -> Estrada | C3: =Sheet1!A11 -> S0001 - 90 Park St | D3: =Sheet1!D11 -> 90-92 Park Street | E3: =Sheet1!B11 -> Retail 2 | F3: =Sheet1!E11 -> Hartford | G3: =Sheet1!F11 -> CT | H3: =Sheet1!G11 -> 06106 | J3: (860) 834-7953 | K3: 2011 Dodge Nitro Truck | L3: Black | M3: RF-84779 | N3: 2019 Chevrolet Cruze | O3: Silver | P3: 796XXP
A4: =Sheet1!H12 -> Joanna | B4: =Sheet1!I12 -> Colon | C4: =Sheet1!A12 -> S0001 - 90 Park St | D4: =Sheet1!D12 -> 96 Park Street | E4: =Sheet1!B12 -> 6 | F4: =Sheet1!E12 -> Hartford | G4: =Sheet1!F12 -> CT | H4: =Sheet1!G12 -> 06106 | J4: (860) 818-5098
A5: =Sheet1!H13 -> German | B5: =Sheet1!I13 -> Santiago | C5: =Sheet1!A13 -> S0001 - 90 Park St | D5: =Sheet1!D13 -> 94 Park Street | E5: =Sheet1!B13 -> 7 - old | F5: =Sheet1!E13 -> Hartford | G5: =Sheet1!F13 -> CT | H5: =Sheet1!G13 -> 06106 | J5: (860) 244-3209 | K5: (Duplicate)
A6: =Sheet1!H14 -> Maritza | B6: =Sheet1!I14 -> Estrada | C6: =Sheet1!A14 -> S0001 - 90 Park St | D6: =Sheet1!D14 -> 96 Park Street | E6: =Sheet1!B14 -> 10 | F6: =Sheet1!E14 -> Hartford | G6: =Sheet1!F14 -> CT | H6: =Sheet1!G14 -> 06106 | J6: (Duplicate)
A7: =Sheet1!H15 -> Rosa | B7: =Sheet1!I15 -> Valdez | C7: =Sheet1!A15 -> S0001 - 90 Park St | D7: =Sheet1!D15 -> 94 Park Street | E7: =Sheet1!B15 -> 5 - B | F7: =Sheet1!E15 -> Hartford | G7: =Sheet1!F15 -> CT | H7: =Sheet1!G15 -> 06106 | J7: (860) 982-9716
A8: =Sheet1!H16 -> Jose | B8: =Sheet1!I16 -> Santiago | C8: =Sheet1!A16 -> S0001 - 90 Park St | D8: =Sheet1!D16 -> 94 Park Street | E8: =Sheet1!B16 -> 5 - B | F8: =Sheet1!E16 -> Hartford | G8: =Sheet1!F16 -> CT | H8: =Sheet1!G16 -> 06106
A9: =Sheet1!H17 -> Wilbert | B9: =Sheet1!I17 -> Lorenzo | C9: =Sheet1!A17 -> S0001 - 90 Park St | D9: =Sheet1!D17 -> 94 Park Street | E9: =Sheet1!B17 -> 5 - C | F9: =Sheet1!E17 -> Hartford | G9: =Sheet1!F17 -> CT | H9: =Sheet1!G17 -> 06106 | J9: (860) 655-0107
A10: =Sheet1!H18 -> Jessica | B10: =Sheet1!I18 -> Rodriguez | C10: =Sheet1!A18 -> S0001 - 90 Park St | D10: =Sheet1!D18 -> 94 Park Street | E10: =Sheet1!B18 -> 9 | F10: =Sheet1!E18 -> Hartford | G10: =Sheet1!F18 -> CT | H10: =Sheet1!G18 -> 06106 | J10: (860) 461-4044 | K10: 2003 Honda Accord | L10: Blue | M10: AM-78297
A11: =Sheet1!H19 -> Steve | B11: =Sheet1!I19 -> Cintron | C11: =Sheet1!A19 -> S0001 - 90 Park St | D11: =Sheet1!D19 -> 94 Park Street | E11: =Sheet1!B19 -> 5 - D | F11: =Sheet1!E19 -> Hartford | G11: =Sheet1!F19 -> CT | H11: =Sheet1!G19 -> 06106 | J11: (860) 960-5042
A12: =Sheet1!H20 -> Amanda | B12: =Sheet1!I20 -> Trevino | C12: =Sheet1!A20 -> S0001 - 90 Park St | D12: =Sheet1!D20 -> 96 Park Street | E12: =Sheet1!B20 -> 4 | F12: =Sheet1!E20 -> Hartford | G12: =Sheet1!F20 -> CT | H12: =Sheet1!G20 -> 06106 | J12: (860) 984-5689
A13: =Sheet1!H21 -> Angelica | B13: =Sheet1!I21 -> Adorno | C13: =Sheet1!A21 -> S0001 - 90 Park St | D13: =Sheet1!D21 -> 96 Park Street | E13: =Sheet1!B21 -> 8 | F13: =Sheet1!E21 -> Hartford | G13: =Sheet1!F21 -> CT | H13: =Sheet1!G21 -> 06106 | J13: (860) 483-1810 | K13: BMW X1
A14: =Sheet1!H22 -> Shara | B14: =Sheet1!I22 -> Ferguson | C14: =Sheet1!A22 -> S0001 - 90 Park St | D14: =Sheet1!D22 -> 90-100 Park Street | E14: =Sheet1!B22 -> 1 | F14: =Sheet1!E22 -> Hartford | G14: =Sheet1!F22 -> CT | H14: =Sheet1!G22 -> 06106 | J14: (860) 331-3667 | K14: 2010 Honda Pilot | L14: Black | M14: BK61474 | N14: 2005 Nissan Altima | O14: White | P14: New Hampshire 5006419
A15: =Sheet1!H23 -> Ashley | B15: =Sheet1!I23 -> Mcquillar | C15: =Sheet1!A23 -> S0001 - 90 Park St | D15: =Sheet1!D23 -> 90-100 Park Street | E15: =Sheet1!B23 -> 3 | F15: =Sheet1!E23 -> Hartford | G15: =Sheet1!F23 -> CT | H15: =Sheet1!G23 -> 06106 | J15: (203) 415-6038
A16: =Sheet1!H24 -> Domingo | B16: =Sheet1!I24 -> Perez-Garcia | C16: =Sheet1!A24 -> S0001 - 90 Park St | D16: =Sheet1!D24 -> 94 Park Street | E16: =Sheet1!B24 -> 5 - E | F16: =Sheet1!E24 -> Hartford | G16: =Sheet1!F24 -> CT | H16: =Sheet1!G24 -> 06106
A17: =Sheet1!H25 -> Cristobal | B17: =Sheet1!I25 -> Rivera | C17: =Sheet1!A25 -> S0001 - 90 Park St | D17: =Sheet1!D25 -> 94 Park Street | E17: =Sheet1!B25 -> 5 - A | F17: =Sheet1!E25 -> Hartford | G17: =Sheet1!F25 -> CT | H17: =Sheet1!G25 -> 06106 | J17: (959) 248-1413
A18: =Sheet1!H26 -> Maritsa | B18: =Sheet1!I26 -> Gonzalez | C18: =Sheet1!A26 -> S0001 - 90 Park St | D18: =Sheet1!D26 -> 90-100 Park Street - 2 | E18: =Sheet1!B26 -> 2 | F18: =Sheet1!E26 -> Hartford | G18: =Sheet1!F26 -> CT | H18: =Sheet1!G26 -> 06106 | J18: (413) 769-0068
A19: =Sheet1!H27 -> German | B19: =Sheet1!I27 -> Santiago | C19: =Sheet1!A27 -> S0001 - 90 Park St | D19: =Sheet1!D27 -> 90-100 Park Street | E19: =Sheet1!B27 -> 7 - A | F19: =Sheet1!E27 -> Hartford | G19: =Sheet1!F27 -> CT | H19: =Sheet1!G27 -> 06106 | J19: (860) 244-3209 | K19: 2004 Jeep Liberty | L19: Brown | M19: BU23143
A20: =Sheet1!H28 -> Natalie | B20: =Sheet1!I28 -> Morales | C20: =Sheet1!A28 -> S0001 - 90 Park St | D20: =Sheet1!D28 -> 90-100 Park Street | E20: =Sheet1!B28 -> 7 - B | F20: =Sheet1!E28 -> Hartford | G20: =Sheet1!F28 -> CT | H20: =Sheet1!G28 -> 06106
A21: =Sheet1!H29 -> Clarissa | B21: =Sheet1!I29 -> Escobar | C21: =Sheet1!A29 -> S0004 - 43 Frank | D21: =Sheet1!D29 -> 43-45 Franklin Avenue | E21: =Sheet1!B29 -> 2N | F21: =Sheet1!E29 -> Hartford | G21: =Sheet1!F29 -> CT | H21: =Sheet1!G29 -> 06114 | J21: (Skip)
A22: =Sheet1!H30 -> Judithlynn | B22: =Sheet1!I30 -> Vail | C22: =Sheet1!A30 -> S0004 - 43 Frank | D22: =Sheet1!D30 -> 43-45 Franklin Avenue | E22: =Sheet1!B30 -> 3N | F22: =Sheet1!E30 -> Hartford | G22: =Sheet1!F30 -> CT | H22: =Sheet1!G30 -> 06114 | J22: (Skip)
A23: =Sheet1!H31 -> Daisy | B23: =Sheet1!I31 -> Ramos | C23: =Sheet1!A31 -> S0004 - 43 Frank | D23: =Sheet1!D31 -> 43-45 Franklin Avenue | E23: =Sheet1!B31 -> 1N | F23: =Sheet1!E31 -> Hartford | G23: =Sheet1!F31 -> CT | H23: =Sheet1!G31 -> 06114 | J23: (Skip)
A24: =Sheet1!H32 -> Valerie | B24: =Sheet1!I32 -> Vazquez | C24: =Sheet1!A32 -> S0004 - 43 Frank | D24: =Sheet1!D32 -> 43-45 Franklin Avenue | E24: =Sheet1!B32 -> 1S | F24: =Sheet1!E32 -> Hartford | G24: =Sheet1!F32 -> CT | H24: =Sheet1!G32 -> 06114 | J24: (Skip)
A25: =Sheet1!H33 -> Bridget | B25: =Sheet1!I33 -> Nimani | C25: =Sheet1!A33 -> S0004 - 43 Frank | D25: =Sheet1!D33 -> 43-45 Franklin Avenue | E25: =Sheet1!B33 -> 3S | F25: =Sheet1!E33 -> Hartford | G25: =Sheet1!F33 -> CT | H25: =Sheet1!G33 -> 06114 | J25: (Skip)
A26: =Sheet1!H34 -> Anthony | B26: =Sheet1!I34 -> Nimani | C26: =Sheet1!A34 -> S0004 - 43 Frank | D26: =Sheet1!D34 -> 43-45 Franklin Avenue | E26: =Sheet1!B34 -> 3S | F26: =Sheet1!E34 -> Hartford | G26: =Sheet1!F34 -> CT | H26: =Sheet1!G34 -> 06114 | J26: (Skip)
A27: =Sheet1!H35 -> Dolores | B27: =Sheet1!I35 -> Arroyo | C27: =Sheet1!A35 -> S0005 - 47 Frank | D27: =Sheet1!D35 -> 47 Franklin Avenue | E27: =Sheet1!B35 -> 3 | F27: =Sheet1!E35 -> Hartford | G27: =Sheet1!F35 -> CT | H27: =Sheet1!G35 -> 06114 | J27: (860) 2069560 | K27: 2014 Electric GD | L27: Black | M27: BP57967
A28: Kishan | B28: Walker | C28: =Sheet1!A36 -> S0005 - 47 Frank | D28: =Sheet1!D36 -> 47 Franklin Avenue | E28: =Sheet1!B36 -> 1 | F28: =Sheet1!E36 -> Hartford | G28: =Sheet1!F36 -> CT | H28: =Sheet1!G36 -> 06114 | K28: Ford Explorer 2016 | L28: Brown | M28: BU41041
A29: =Sheet1!H37 -> Alexandra | B29: =Sheet1!I37 -> Baron | C29: =Sheet1!A37 -> S0005 - 47 Frank | D29: =Sheet1!D37 -> 47 Franklin Avenue | E29: =Sheet1!B37 -> 1 | F29: =Sheet1!E37 -> Hartford | G29: =Sheet1!F37 -> CT | H29: =Sheet1!G37 -> 06114 | J29: (Skip)
A30: =Sheet1!H38 -> Carlos | B30: =Sheet1!I38 -> Nieves | C30: =Sheet1!A38 -> S0005 - 47 Frank | D30: =Sheet1!D38 -> 47 Franklin Avenue | E30: =Sheet1!B38 -> 4 | F30: =Sheet1!E38 -> Hartford | G30: =Sheet1!F38 -> CT | H30: =Sheet1!G38 -> 06114 | J30: (Skip)
A31: =Sheet1!H39 -> Cynthia | B31: =Sheet1!I39 -> Burnham | C31: =Sheet1!A39 -> S0005 - 47 Frank | D31: =Sheet1!D39 -> 47 Franklin Avenue | E31: =Sheet1!B39 -> 2 | F31: =Sheet1!E39 -> Hartford | G31: =Sheet1!F39 -> CT | H31: =Sheet1!G39 -> 06114 | J31: (860) 656-5984 | K31: Nissan Sentra 2005 | L31: Tan | M31: 4XF814
A32: =Sheet1!H40 -> Lui | B32: =Sheet1!I40 -> Maldonado | C32: =Sheet1!A40 -> S0006 - 15 Whitmore | D32: =Sheet1!D40 -> 15 Whitmore Street | E32: =Sheet1!B40 -> 1W - B & C | F32: =Sheet1!E40 -> Hartford | G32: =Sheet1!F40 -> CT | H32: =Sheet1!G40 -> 06114 | J32: (860) 7897247 | K32: 2011 Lincoln MKZ 4 Door sedan | L32: Burgundy | M32: BM45035
A33: =Sheet1!H41 -> Nizi | B33: =Sheet1!I41 -> Santiago | C33: =Sheet1!A41 -> S0006 - 15 Whitmore | D33: =Sheet1!D41 -> 15-17 Whitmore Street | E33: =Sheet1!B41 -> 1W - A | F33: =Sheet1!E41 -> Hartford | G33: =Sheet1!F41 -> CT | H33: =Sheet1!G41 -> 06114 | J33: (860) 488-7659
A34: =Sheet1!H42 -> Martin | B34: =Sheet1!I42 -> Cruz Mamani | C34: =Sheet1!A42 -> S0006 - 15 Whitmore | D34: =Sheet1!D42 -> 15-17 Whitmore Street - | E34: =Sheet1!B42 -> 3W | F34: =Sheet1!E42 -> Hartford | G34: =Sheet1!F42 -> CT | H34: =Sheet1!G42 -> 06114 | J34: (860) 816-7003 | K34: 2008 Subaru Outback | L34: Blue | M34: BS86380
A35: =Sheet1!H43 -> Angelina | B35: =Sheet1!I43 -> Dalessandro | C35: =Sheet1!A43 -> S0006 - 15 Whitmore | D35: =Sheet1!D43 -> 15-17 Whitmore Street | E35: =Sheet1!B43 -> 3E | F35: =Sheet1!E43 -> Hartford | G35: =Sheet1!F43 -> CT | H35: =Sheet1!G43 -> 06114 | J35: (203) 833-0869 | K35: 2008 Honda | L35: Black | M35: BR35201
A36: =Sheet1!H44 -> Tania | B36: =Sheet1!I44 -> Smith | C36: =Sheet1!A44 -> S0006 - 15 Whitmore | D36: =Sheet1!D44 -> 15 Whitmore Street | E36: =Sheet1!B44 -> 2E | F36: =Sheet1!E44 -> Hartford | G36: =Sheet1!F44 -> CT | H36: =Sheet1!G44 -> 06114 | J36: (860) 773-9038
A37: =Sheet1!H45 -> Shawneice | B37: =Sheet1!I45 -> Ragland | C37: =Sheet1!A45 -> S0006 - 15 Whitmore | D37: =Sheet1!D45 -> 15-17 Whitmore Street | E37: =Sheet1!B45 -> 1E | F37: =Sheet1!E45 -> Hartford | G37: =Sheet1!F45 -> CT | H37: =Sheet1!G45 -> 06114 | J37: (860) 280-4665 | K37: Mercedes Benz ML350 | L37: Silver | M37: BF77668
A38: =Sheet1!H46 -> Destiny | B38: =Sheet1!I46 -> Peele | C38: =Sheet1!A46 -> S0006 - 15 Whitmore | D38: =Sheet1!D46 -> 15 Whitmore Street | E38: =Sheet1!B46 -> 2W | F38: =Sheet1!E46 -> Hartford | G38: =Sheet1!F46 -> CT | H38: =Sheet1!G46 -> 06114 | J38: (959) 208-6327
A39: =Sheet1!H47 -> Shaneequa | B39: =Sheet1!I47 -> Allen | C39: =Sheet1!A47 -> S0007 - 36 Whit | D39: =Sheet1!D47 -> 36 Whitmore Street | E39: =Sheet1!B47 -> 2E | F39: =Sheet1!E47 -> Hartford | G39: =Sheet1!F47 -> CT | H39: =Sheet1!G47 -> 06114 | J39: (860) 719-7463 | K39: 2010 Dodge Caliber | L39: Gold | M39: BU01442
A40: =Sheet1!H48 -> Ramon | B40: =Sheet1!I48 -> Casiano | C40: =Sheet1!A48 -> S0007 - 36 Whit | D40: =Sheet1!D48 -> 36 Whitmore Street | E40: =Sheet1!B48 -> 3W | F40: =Sheet1!E48 -> Hartford | G40: =Sheet1!F48 -> CT | H40: =Sheet1!G48 -> 06114 | J40: (860) 967-4098 | K40: 2016 Ford Expedition | L40: Black | M40: BU01800
...
